<?xml version="1.0" ?>
<sdf version="1.4">
	<model name="robot">
		<link name="body_link">
			<pose>0 0 0.19649999999999998 0 0 0</pose>
			<visual name="body_link_vis">
				<geometry>
					<box>
						<size>0.3 0.6 0.049999999999999996</size>
					</box>
				</geometry>
			</visual>
			<collision name="body_link_col">
				<geometry>
					<box>
						<size>0.3 0.6 0.049999999999999996</size>
					</box>
				</geometry>
			</collision>
		</link>
		<link name="susp_1">
			<pose>0.13125 -0.22499999999999998 0.12375 0 0 0</pose>
			<visual name="susp_1_vis">
				<geometry>
					<cylinder>
						<radius>0.01875</radius>
						<length>0.0975</length>
					</cylinder>
				</geometry>
			</visual>
			<collision name="susp_1_col">
				<geometry>
					<cylinder>
						<radius>0.01875</radius>
						<length>0.0975</length>
					</cylinder>
				</geometry>
			</collision>
		</link>
		<link name="wheel_1">
			<pose>0.18125000000000002 -0.22499999999999998 0.075 0 1.5707963267948966 0</pose>
			<visual name="wheel_1_vis">
				<geometry>
					<cylinder>
						<radius>0.075</radius>
						<length>0.05769230769230769</length>
					</cylinder>
				</geometry>
			</visual>
			<collision name="wheel_1_col">
				<geometry>
					<cylinder>
						<radius>0.075</radius>
						<length>0.05769230769230769</length>
					</cylinder>
				</geometry>
			</collision>
		</link>
		<joint name="susp1_body" type="fixed">
			<pose>0 0 0.04875 0 0 0</pose>
			<child>susp_1</child>
			<parent>body_link</parent>
		</joint>
		<joint name="susp_axel_1" type="fixed">
			<pose>0 0 -0.025 0 0 0</pose>
			<child>axel_1</child>
			<parent>susp_1</parent>
		</joint>
		<link name="susp_2">
			<pose>0.13125 0.22499999999999998 0.12375 0 0 0</pose>
			<visual name="susp_2_vis">
				<geometry>
					<cylinder>
						<radius>0.01875</radius>
						<length>0.0975</length>
					</cylinder>
				</geometry>
			</visual>
			<collision name="susp_2_col">
				<geometry>
					<cylinder>
						<radius>0.01875</radius>
						<length>0.0975</length>
					</cylinder>
				</geometry>
			</collision>
		</link>
		<link name="wheel_2">
			<pose>0.18125000000000002 0.22499999999999998 0.075 0 1.5707963267948966 0</pose>
			<visual name="wheel_2_vis">
				<geometry>
					<cylinder>
						<radius>0.075</radius>
						<length>0.05769230769230769</length>
					</cylinder>
				</geometry>
			</visual>
			<collision name="wheel_2_col">
				<geometry>
					<cylinder>
						<radius>0.075</radius>
						<length>0.05769230769230769</length>
					</cylinder>
				</geometry>
			</collision>
		</link>
		<joint name="susp2_body" type="fixed">
			<pose>0 0 0.04875 0 0 0</pose>
			<child>susp_2</child>
			<parent>body_link</parent>
		</joint>
		<joint name="susp_axel_2" type="fixed">
			<pose>0 0 -0.025 0 0 0</pose>
			<child>axel_2</child>
			<parent>susp_2</parent>
		</joint>
		<link name="susp_4">
			<pose>-0.13125 -0.22499999999999998 0.12375 0 0 0</pose>
			<visual name="susp_4_vis">
				<geometry>
					<cylinder>
						<radius>0.01875</radius>
						<length>0.0975</length>
					</cylinder>
				</geometry>
			</visual>
			<collision name="susp_4_col">
				<geometry>
					<cylinder>
						<radius>0.01875</radius>
						<length>0.0975</length>
					</cylinder>
				</geometry>
			</collision>
		</link>
		<link name="wheel_4">
			<pose>-0.18125000000000002 -0.22499999999999998 0.075 0 1.5707963267948966 0</pose>
			<visual name="wheel_4_vis">
				<geometry>
					<cylinder>
						<radius>0.075</radius>
						<length>0.05769230769230769</length>
					</cylinder>
				</geometry>
			</visual>
			<collision name="wheel_4_col">
				<geometry>
					<cylinder>
						<radius>0.075</radius>
						<length>0.05769230769230769</length>
					</cylinder>
				</geometry>
			</collision>
		</link>
		<joint name="susp4_body" type="fixed">
			<pose>0 0 0.04875 0 0 0</pose>
			<child>susp_4</child>
			<parent>body_link</parent>
		</joint>
		<joint name="susp_axel_4" type="fixed">
			<pose>0 0 0.025 0 0 0</pose>
			<child>axel_4</child>
			<parent>susp_4</parent>
		</joint>
		<link name="axel_1">
			<pose>0.15625 -0.22499999999999998 0.075 0 1.5707963267948966 0</pose>
			<visual name="axel_1_vis">
				<geometry>
					<cylinder>
						<radius>0.012</radius>
						<length>0.05</length>
					</cylinder>
				</geometry>
			</visual>
			<collision name="axel_1_col">
				<geometry>
					<cylinder>
						<radius>0.012</radius>
						<length>0.05</length>
					</cylinder>
				</geometry>
			</collision>
		</link>
		<joint name="axel_wheel_1" type="revolute">
			<pose>0 0 -0.028846153846153844 0 0 0</pose>
			<child>wheel_1</child>
			<parent>axel_1</parent>
			<axis>
				<xyz>1 0 0</xyz>
				<dynamics>
					<friction>0.05</friction>
					<damping>0.03</damping>
				</dynamics>
			</axis>
		</joint>
		<link name="axel_2">
			<pose>0.15625 0.22499999999999998 0.075 0 1.5707963267948966 0</pose>
			<visual name="axel_2_vis">
				<geometry>
					<cylinder>
						<radius>0.012</radius>
						<length>0.05</length>
					</cylinder>
				</geometry>
			</visual>
			<collision name="axel_2_col">
				<geometry>
					<cylinder>
						<radius>0.012</radius>
						<length>0.05</length>
					</cylinder>
				</geometry>
			</collision>
		</link>
		<joint name="axel_wheel_2" type="revolute">
			<pose>0 0 -0.028846153846153844 0 0 0</pose>
			<child>wheel_2</child>
			<parent>axel_2</parent>
			<axis>
				<xyz>1 0 0</xyz>
				<dynamics>
					<friction>0.05</friction>
					<damping>0.03</damping>
				</dynamics>
			</axis>
		</joint>
		<link name="axel_3">
			<pose>-0.15625 0.22499999999999998 0.075 0 1.5707963267948966 0</pose>
			<visual name="axel_3_vis">
				<geometry>
					<cylinder>
						<radius>0.012</radius>
						<length>0.05</length>
					</cylinder>
				</geometry>
			</visual>
			<collision name="axel_3_col">
				<geometry>
					<cylinder>
						<radius>0.012</radius>
						<length>0.05</length>
					</cylinder>
				</geometry>
			</collision>
		</link>
		<joint name="axel_wheel_3" type="revolute">
			<pose>0 0 0.028846153846153844 0 0 0</pose>
			<child>wheel_3</child>
			<parent>axel_3</parent>
			<axis>
				<xyz>1 0 0</xyz>
				<dynamics>
					<friction>0.05</friction>
					<damping>0.03</damping>
				</dynamics>
			</axis>
		</joint>
		<link name="axel_4">
			<pose>-0.15625 -0.22499999999999998 0.075 0 1.5707963267948966 0</pose>
			<visual name="axel_4_vis">
				<geometry>
					<cylinder>
						<radius>0.012</radius>
						<length>0.05</length>
					</cylinder>
				</geometry>
			</visual>
			<collision name="axel_4_col">
				<geometry>
					<cylinder>
						<radius>0.012</radius>
						<length>0.05</length>
					</cylinder>
				</geometry>
			</collision>
		</link>
		<joint name="axel_wheel_4" type="revolute">
			<pose>0 0 0.028846153846153844 0 0 0</pose>
			<child>wheel_4</child>
			<parent>axel_4</parent>
			<axis>
				<xyz>1 0 0</xyz>
				<dynamics>
					<friction>0.05</friction>
					<damping>0.03</damping>
				</dynamics>
			</axis>
		</joint>
		<link name="susp_3">
			<pose>-0.13125 0.22499999999999998 0.12375 0 0 0</pose>
			<visual name="susp_3_vis">
				<geometry>
					<cylinder>
						<radius>0.01875</radius>
						<length>0.0975</length>
					</cylinder>
				</geometry>
			</visual>
			<collision name="susp_3_col">
				<geometry>
					<cylinder>
						<radius>0.01875</radius>
						<length>0.0975</length>
					</cylinder>
				</geometry>
			</collision>
		</link>
		<link name="wheel_3">
			<pose>-0.18125000000000002 0.22499999999999998 0.075 0 1.5707963267948966 0</pose>
			<visual name="wheel_3_vis">
				<geometry>
					<cylinder>
						<radius>0.075</radius>
						<length>0.05769230769230769</length>
					</cylinder>
				</geometry>
			</visual>
			<collision name="wheel_3_col">
				<geometry>
					<cylinder>
						<radius>0.075</radius>
						<length>0.05769230769230769</length>
					</cylinder>
				</geometry>
			</collision>
		</link>
		<joint name="susp3_body" type="fixed">
			<pose>0 0 0.04875 0 0 0</pose>
			<child>susp_3</child>
			<parent>body_link</parent>
		</joint>
		<joint name="susp_axel_3" type="fixed">
			<pose>0 0 0.025 0 0 0</pose>
			<child>axel_3</child>
			<parent>susp_3</parent>
		</joint>
		<plugin filename="libgazebo_ros_diff_drive.so" name="differential_drive_controller">
			<alwaysOn>true</alwaysOn>
			<updateRate>20</updateRate>
			<leftJoint>axel_wheel_1</leftJoint>
			<rightJoint>axel_wheel_4</rightJoint>
			<wheelSeparation>0.21250000000000005</wheelSeparation>
			<wheelDiameter>0.15</wheelDiameter>
			<wheelTorque>20</wheelTorque>
			<commandTopic>cmd_wheel</commandTopic>
			<odometryTopic>wheel</odometryTopic>
			<odometryFrame>odom</odometryFrame>
			<robotBaseFrame>base_footprint</robotBaseFrame>
			<rosDebugLevel>1</rosDebugLevel>
			<wheelAcceleration>2</wheelAcceleration>
		</plugin>
	</model>
</sdf>
