<?xml version="1.0" ?>
<sdf version="1.6">
	<model name="robot">
		<link name="body_link">
			<pose>0 0 0.19649999999999998 0 0 0</pose>
			<inertial>
				<inertia>
					<ixx>0.30208333</ixx>
					<iyy>0.07708333</iyy>
					<izz>0.37500000</izz>
				</inertia>
				<mass>10.00000000</mass>
			</inertial>
			<visual name="body_link_vis">
				<geometry>
					<box>
						<size>0.3 0.6 0.049999999999999996</size>
					</box>
				</geometry>
			</visual>
			<collision name="body_link_col">
				<geometry>
					<box>
						<size>0.3 0.6 0.049999999999999996</size>
					</box>
				</geometry>
			</collision>
		</link>
		<link name="susp_1">
			<pose>0.13125 -0.22499999999999998 0.12375 0 0 0</pose>
			<inertial>
				<inertia>
					<ixx>0.00088008</ixx>
					<iyy>0.00088008</iyy>
					<izz>0.00017578</izz>
				</inertia>
				<mass>1.00000000</mass>
			</inertial>
			<visual name="susp_1_vis">
				<geometry>
					<cylinder>
						<radius>0.01875</radius>
						<length>0.0975</length>
					</cylinder>
				</geometry>
			</visual>
			<collision name="susp_1_col">
				<geometry>
					<cylinder>
						<radius>0.01875</radius>
						<length>0.0975</length>
					</cylinder>
				</geometry>
			</collision>
		</link>
		<link name="wheel_1">
			<pose>0.18125000000000002 -0.22499999999999998 0.075 0 1.5707963267948966 0</pose>
			<inertial>
				<inertia>
					<ixx>0.00281250</ixx>
					<iyy>0.00168362</iyy>
					<izz>0.00168362</izz>
				</inertia>
				<mass>1.00000000</mass>
			</inertial>
			<visual name="wheel_1_vis">
				<geometry>
					<cylinder>
						<radius>0.075</radius>
						<length>0.05769230769230769</length>
					</cylinder>
				</geometry>
			</visual>
			<collision name="wheel_1_col">
				<geometry>
					<cylinder>
						<radius>0.075</radius>
						<length>0.05769230769230769</length>
					</cylinder>
				</geometry>
			</collision>
		</link>
		<joint name="susp1_body" type="fixed">
			<pose>0 0 0.04875 0 0 0</pose>
			<child>susp_1</child>
			<parent>body_link</parent>
		</joint>
		<joint name="susp_axel_1" type="fixed">
			<pose>0 0 -0.025 0 0 0</pose>
			<child>axel_1</child>
			<parent>susp_1</parent>
		</joint>
		<link name="susp_2">
			<pose>0.13125 0.22499999999999998 0.12375 0 0 0</pose>
			<inertial>
				<inertia>
					<ixx>0.00088008</ixx>
					<iyy>0.00088008</iyy>
					<izz>0.00017578</izz>
				</inertia>
				<mass>1.00000000</mass>
			</inertial>
			<visual name="susp_2_vis">
				<geometry>
					<cylinder>
						<radius>0.01875</radius>
						<length>0.0975</length>
					</cylinder>
				</geometry>
			</visual>
			<collision name="susp_2_col">
				<geometry>
					<cylinder>
						<radius>0.01875</radius>
						<length>0.0975</length>
					</cylinder>
				</geometry>
			</collision>
		</link>
		<link name="wheel_2">
			<pose>0.18125000000000002 0.22499999999999998 0.075 0 1.5707963267948966 0</pose>
			<inertial>
				<inertia>
					<ixx>0.00281250</ixx>
					<iyy>0.00168362</iyy>
					<izz>0.00168362</izz>
				</inertia>
				<mass>1.00000000</mass>
			</inertial>
			<visual name="wheel_2_vis">
				<geometry>
					<cylinder>
						<radius>0.075</radius>
						<length>0.05769230769230769</length>
					</cylinder>
				</geometry>
			</visual>
			<collision name="wheel_2_col">
				<geometry>
					<cylinder>
						<radius>0.075</radius>
						<length>0.05769230769230769</length>
					</cylinder>
				</geometry>
			</collision>
		</link>
		<joint name="susp2_body" type="fixed">
			<pose>0 0 0.04875 0 0 0</pose>
			<child>susp_2</child>
			<parent>body_link</parent>
		</joint>
		<joint name="susp_axel_2" type="fixed">
			<pose>0 0 -0.025 0 0 0</pose>
			<child>axel_2</child>
			<parent>susp_2</parent>
		</joint>
		<link name="susp_4">
			<pose>-0.13125 -0.22499999999999998 0.12375 0 0 0</pose>
			<inertial>
				<inertia>
					<ixx>0.00088008</ixx>
					<iyy>0.00088008</iyy>
					<izz>0.00017578</izz>
				</inertia>
				<mass>1.00000000</mass>
			</inertial>
			<visual name="susp_4_vis">
				<geometry>
					<cylinder>
						<radius>0.01875</radius>
						<length>0.0975</length>
					</cylinder>
				</geometry>
			</visual>
			<collision name="susp_4_col">
				<geometry>
					<cylinder>
						<radius>0.01875</radius>
						<length>0.0975</length>
					</cylinder>
				</geometry>
			</collision>
		</link>
		<link name="wheel_4">
			<pose>-0.18125000000000002 -0.22499999999999998 0.075 0 1.5707963267948966 0</pose>
			<inertial>
				<inertia>
					<ixx>0.00281250</ixx>
					<iyy>0.00168362</iyy>
					<izz>0.00168362</izz>
				</inertia>
				<mass>1.00000000</mass>
			</inertial>
			<visual name="wheel_4_vis">
				<geometry>
					<cylinder>
						<radius>0.075</radius>
						<length>0.05769230769230769</length>
					</cylinder>
				</geometry>
			</visual>
			<collision name="wheel_4_col">
				<geometry>
					<cylinder>
						<radius>0.075</radius>
						<length>0.05769230769230769</length>
					</cylinder>
				</geometry>
			</collision>
		</link>
		<joint name="susp4_body" type="fixed">
			<pose>0 0 0.04875 0 0 0</pose>
			<child>susp_4</child>
			<parent>body_link</parent>
		</joint>
		<joint name="susp_axel_4" type="fixed">
			<pose>0 0 0.025 0 0 0</pose>
			<child>axel_4</child>
			<parent>susp_4</parent>
		</joint>
		<link name="axel_1">
			<pose>0.15625 -0.22499999999999998 0.075 0 1.5707963267948966 0</pose>
			<inertial>
				<inertia>
					<ixx>0.00003600</ixx>
					<iyy>0.00012217</iyy>
					<izz>0.00012217</izz>
				</inertia>
				<mass>0.50000000</mass>
			</inertial>
			<visual name="axel_1_vis">
				<geometry>
					<cylinder>
						<radius>0.012</radius>
						<length>0.05</length>
					</cylinder>
				</geometry>
			</visual>
			<collision name="axel_1_col">
				<geometry>
					<cylinder>
						<radius>0.012</radius>
						<length>0.05</length>
					</cylinder>
				</geometry>
			</collision>
		</link>
		<joint name="axel_wheel_1" type="revolute">
			<pose>0 0 -0.028846153846153844 0 -1.5707963267948966 0</pose>
			<child>wheel_1</child>
			<parent>axel_1</parent>
			<axis>
				<xyz>1 0 0</xyz>
				<dynamics>
					<friction>0.05</friction>
					<damping>0.03</damping>
				</dynamics>
			</axis>
		</joint>
		<link name="axel_2">
			<pose>0.15625 0.22499999999999998 0.075 0 1.5707963267948966 0</pose>
			<inertial>
				<inertia>
					<ixx>0.00003600</ixx>
					<iyy>0.00012217</iyy>
					<izz>0.00012217</izz>
				</inertia>
				<mass>0.50000000</mass>
			</inertial>
			<visual name="axel_2_vis">
				<geometry>
					<cylinder>
						<radius>0.012</radius>
						<length>0.05</length>
					</cylinder>
				</geometry>
			</visual>
			<collision name="axel_2_col">
				<geometry>
					<cylinder>
						<radius>0.012</radius>
						<length>0.05</length>
					</cylinder>
				</geometry>
			</collision>
		</link>
		<joint name="axel_wheel_2" type="revolute">
			<pose>0 0 -0.028846153846153844 0 -1.5707963267948966 0</pose>
			<child>wheel_2</child>
			<parent>axel_2</parent>
			<axis>
				<xyz>1 0 0</xyz>
				<dynamics>
					<friction>0.05</friction>
					<damping>0.03</damping>
				</dynamics>
			</axis>
		</joint>
		<link name="axel_3">
			<pose>-0.15625 0.22499999999999998 0.075 0 1.5707963267948966 0</pose>
			<inertial>
				<inertia>
					<ixx>0.00003600</ixx>
					<iyy>0.00012217</iyy>
					<izz>0.00012217</izz>
				</inertia>
				<mass>0.50000000</mass>
			</inertial>
			<visual name="axel_3_vis">
				<geometry>
					<cylinder>
						<radius>0.012</radius>
						<length>0.05</length>
					</cylinder>
				</geometry>
			</visual>
			<collision name="axel_3_col">
				<geometry>
					<cylinder>
						<radius>0.012</radius>
						<length>0.05</length>
					</cylinder>
				</geometry>
			</collision>
		</link>
		<joint name="axel_wheel_3" type="revolute">
			<pose>0 0 0.028846153846153844 0 -1.5707963267948966 0</pose>
			<child>wheel_3</child>
			<parent>axel_3</parent>
			<axis>
				<xyz>1 0 0</xyz>
				<dynamics>
					<friction>0.05</friction>
					<damping>0.03</damping>
				</dynamics>
			</axis>
		</joint>
		<link name="axel_4">
			<pose>-0.15625 -0.22499999999999998 0.075 0 1.5707963267948966 0</pose>
			<inertial>
				<inertia>
					<ixx>0.00003600</ixx>
					<iyy>0.00012217</iyy>
					<izz>0.00012217</izz>
				</inertia>
				<mass>0.50000000</mass>
			</inertial>
			<visual name="axel_4_vis">
				<geometry>
					<cylinder>
						<radius>0.012</radius>
						<length>0.05</length>
					</cylinder>
				</geometry>
			</visual>
			<collision name="axel_4_col">
				<geometry>
					<cylinder>
						<radius>0.012</radius>
						<length>0.05</length>
					</cylinder>
				</geometry>
			</collision>
		</link>
		<joint name="axel_wheel_4" type="revolute">
			<pose>0 0 0.028846153846153844 0 -1.5707963267948966 0</pose>
			<child>wheel_4</child>
			<parent>axel_4</parent>
			<axis>
				<xyz>1 0 0</xyz>
				<dynamics>
					<friction>0.05</friction>
					<damping>0.03</damping>
				</dynamics>
			</axis>
		</joint>
		<link name="susp_3">
			<pose>-0.13125 0.22499999999999998 0.12375 0 0 0</pose>
			<inertial>
				<inertia>
					<ixx>0.00088008</ixx>
					<iyy>0.00088008</iyy>
					<izz>0.00017578</izz>
				</inertia>
				<mass>1.00000000</mass>
			</inertial>
			<visual name="susp_3_vis">
				<geometry>
					<cylinder>
						<radius>0.01875</radius>
						<length>0.0975</length>
					</cylinder>
				</geometry>
			</visual>
			<collision name="susp_3_col">
				<geometry>
					<cylinder>
						<radius>0.01875</radius>
						<length>0.0975</length>
					</cylinder>
				</geometry>
			</collision>
		</link>
		<link name="wheel_3">
			<pose>-0.18125000000000002 0.22499999999999998 0.075 0 1.5707963267948966 0</pose>
			<inertial>
				<inertia>
					<ixx>0.00281250</ixx>
					<iyy>0.00168362</iyy>
					<izz>0.00168362</izz>
				</inertia>
				<mass>1.00000000</mass>
			</inertial>
			<visual name="wheel_3_vis">
				<geometry>
					<cylinder>
						<radius>0.075</radius>
						<length>0.05769230769230769</length>
					</cylinder>
				</geometry>
			</visual>
			<collision name="wheel_3_col">
				<geometry>
					<cylinder>
						<radius>0.075</radius>
						<length>0.05769230769230769</length>
					</cylinder>
				</geometry>
			</collision>
		</link>
		<joint name="susp3_body" type="fixed">
			<pose>0 0 0.04875 0 0 0</pose>
			<child>susp_3</child>
			<parent>body_link</parent>
		</joint>
		<joint name="susp_axel_3" type="fixed">
			<pose>0 0 0.025 0 0 0</pose>
			<child>axel_3</child>
			<parent>susp_3</parent>
		</joint>
		<plugin filename="libwheel_plugin.so" name="wheel_ctr">
			<prefix>wheely/steering</prefix>
			<velPubTopic>cmd_wheel</velPubTopic>
			<odometrySubTopic>odom</odometrySubTopic>
			<kp>1.5</kp>
			<ki>6.2</ki>
			<kd>1.2</kd>
			<dt>0.01</dt>
			<turnAccuracy>0.03</turnAccuracy>
		</plugin>
		<plugin filename="libgazebo_ros_skid_steer_drive.so" name="skid_steer_controller">
			<alwaysOn>true</alwaysOn>
			<updateRate>1200</updateRate>
			<robotNamespace>wheely/steering</robotNamespace>
			<leftFrontJoint>axel_wheel_4</leftFrontJoint>
			<rightFrontJoint>axel_wheel_1</rightFrontJoint>
			<leftRearJoint>axel_wheel_3</leftRearJoint>
			<rightRearJoint>axel_wheel_2</rightRearJoint>
			<wheelSeparation>0.30480769230769234</wheelSeparation>
			<wheelDiameter>0.15</wheelDiameter>
			<torque>100</torque>
			<commandTopic>cmd_wheel</commandTopic>
			<odometryTopic>odom</odometryTopic>
			<odometryFrame>odom</odometryFrame>
			<broadcastTF>1</broadcastTF>
			<robotBaseFrame>body_link</robotBaseFrame>
		</plugin>
		<link name="IR_link">
			<pose>0 -0.27999999999999997 0.25149999999999995 0 0 0</pose>
			<inertial>
				<inertia>
					<ixx>0.00000100</ixx>
					<iyy>0.00000100</iyy>
					<izz>0.00000100</izz>
				</inertia>
				<mass>0.00001000</mass>
			</inertial>
			<visual name="IR_link_vis">
				<geometry>
					<cylinder>
						<radius>0.02</radius>
						<length>0.06</length>
					</cylinder>
				</geometry>
			</visual>
			<collision name="IR_link_col">
				<geometry>
					<cylinder>
						<radius>0.02</radius>
						<length>0.06</length>
					</cylinder>
				</geometry>
			</collision>
			<sensor name="ir_sensor" type="ray">
				<visualize>true</visualize>
				<update_rate>50</update_rate>
				<pose>0 -0.02 0.03 0 0 -1.5707963267948966</pose>
				<plugin filename="libgazebo_ros_range.so" name="gazebo_ros_range">
					<gaussianNoise>0.0</gaussianNoise>
					<alwaysOn>true</alwaysOn>
					<updateRate>50</updateRate>
					<topicName>wheely/sensor/ir</topicName>
					<frameName>IR_link</frameName>
					<radiation>infrared</radiation>
					<fov>0.2967</fov>
				</plugin>
				<ray>
					<scan>
						<horizontal>
							<samples>1</samples>
							<resolution>1</resolution>
							<min_angle>0</min_angle>
							<max_angle>0</max_angle>
						</horizontal>
						<vertical>
							<samples>1</samples>
							<resolution>1</resolution>
							<min_angle>0</min_angle>
							<max_angle>0</max_angle>
						</vertical>
					</scan>
					<range>
						<min>0.01</min>
						<max>50</max>
						<resolution>1</resolution>
					</range>
				</ray>
				<always_on>true</always_on>
			</sensor>
		</link>
		<joint name="IR_body_joint" type="revolute">
			<pose>0 0 -0.03 0 0 0</pose>
			<child>IR_link</child>
			<parent>body_link</parent>
			<axis>
				<xyz>0 0 1</xyz>
				<dynamics>
					<friction>0.05</friction>
					<damping>0.03</damping>
				</dynamics>
			</axis>
			<physics>
				<ode>
					<cfm_damping>1</cfm_damping>
					<implicit_spring_damper>1</implicit_spring_damper>
				</ode>
			</physics>
		</joint>
		<plugin filename="libIR_sensor.so" name="IR_sensor_ctrl"/>
		<link name="Short_IR_Link">
			<pose>0 -0.31 0.19649999999999998 0 0 0</pose>
			<inertial>
				<inertia>
					<ixx>0.00000100</ixx>
					<iyy>0.00000100</iyy>
					<izz>0.00000100</izz>
				</inertia>
				<mass>0.00001000</mass>
			</inertial>
			<visual name="Short_IR_Link_vis">
				<geometry>
					<box>
						<size>0.02 0.02 0.02</size>
					</box>
				</geometry>
			</visual>
			<collision name="Short_IR_Link_col">
				<geometry>
					<box>
						<size>0.02 0.02 0.02</size>
					</box>
				</geometry>
			</collision>
			<sensor name="ir_sensor_shrt" type="ray">
				<visualize>true</visualize>
				<update_rate>50</update_rate>
				<pose>0 -0.02 0 0 0 -1.5707963267948966</pose>
				<plugin filename="libgazebo_ros_range.so" name="gazebo_ros_range_shrt">
					<gaussianNoise>0.0</gaussianNoise>
					<alwaysOn>true</alwaysOn>
					<updateRate>50</updateRate>
					<topicName>wheely/sensor/ir_shrt</topicName>
					<frameName>Short_IR_Link</frameName>
					<radiation>infrared</radiation>
					<fov>0.2967</fov>
				</plugin>
				<ray>
					<scan>
						<horizontal>
							<samples>180</samples>
							<resolution>1</resolution>
							<min_angle>-1.3962634015954636</min_angle>
							<max_angle>1.3962634015954636</max_angle>
						</horizontal>
						<vertical>
							<samples>1</samples>
							<resolution>1</resolution>
							<min_angle>0</min_angle>
							<max_angle>0</max_angle>
						</vertical>
					</scan>
					<range>
						<min>0.01</min>
						<max>0.45</max>
						<resolution>1</resolution>
					</range>
				</ray>
				<always_on>true</always_on>
			</sensor>
		</link>
		<joint name="Short_IR_Body_Jt" type="fixed">
			<pose>0 0.01 0 0 0 0</pose>
			<child>Short_IR_Link</child>
			<parent>body_link</parent>
		</joint>
	</model>
</sdf>
