<?xml version="1.0" ?>
<sdf version="1.4">
	<model name="robot">
		<link name="body_link">
			<pose>0 0 0.19649999999999998 0 0 0</pose>
			<visual name="body_link_vis">
				<geometry>
					<box>
						<size>0.3 0.6 0.049999999999999996</size>
					</box>
				</geometry>
			</visual>
			<collision name="body_link_col">
				<geometry>
					<box>
						<size>0.3 0.6 0.049999999999999996</size>
					</box>
				</geometry>
			</collision>
		</link>
		<link name="susp_1">
			<pose>0.13125 -0.22499999999999998 0.12375 0 0 0</pose>
			<visual name="susp_1_vis">
				<geometry>
					<cylinder>
						<radius>0.01875</radius>
						<length>0.0975</length>
					</cylinder>
				</geometry>
			</visual>
			<collision name="susp_1_col">
				<geometry>
					<cylinder>
						<radius>0.01875</radius>
						<length>0.0975</length>
					</cylinder>
				</geometry>
			</collision>
		</link>
		<link name="wheel_1">
			<pose>0.17984615384615385 -0.22499999999999998 0.075 0 1.5707 0</pose>
			<visual name="wheel_1_vis">
				<geometry>
					<cylinder>
						<radius>0.075</radius>
						<length>0.05769230769230769</length>
					</cylinder>
				</geometry>
			</visual>
			<collision name="wheel_1_col">
				<geometry>
					<cylinder>
						<radius>0.075</radius>
						<length>0.05769230769230769</length>
					</cylinder>
				</geometry>
			</collision>
		</link>
		<joint name="susp1_body" type="revolute">
			<pose>0 0 0.04875 0 0 0</pose>
			<child>susp_1</child>
			<parent>body_link</parent>
			<axis>
				<xyz>0 0 1</xyz>
				<dynamics>
					<friction>0.5</friction>
					<damping>0.3</damping>
				</dynamics>
				<limit>
					<upper>1.0471975511965976</upper>
					<lower>-1.0471975511965976</lower>
				</limit>
			</axis>
		</joint>
		<joint name="susp_wheel_1" type="revolute">
			<pose>0 0 0 0 0 0</pose>
			<child>wheel_1</child>
			<parent>susp_1</parent>
			<axis>
				<xyz>1 0 0</xyz>
				<dynamics>
					<friction>0.5</friction>
					<damping>0.3</damping>
				</dynamics>
			</axis>
		</joint>
		<link name="susp_2">
			<pose>0.13125 0.22499999999999998 0.12375 0 0 0</pose>
			<visual name="susp_2_vis">
				<geometry>
					<cylinder>
						<radius>0.01875</radius>
						<length>0.0975</length>
					</cylinder>
				</geometry>
			</visual>
			<collision name="susp_2_col">
				<geometry>
					<cylinder>
						<radius>0.01875</radius>
						<length>0.0975</length>
					</cylinder>
				</geometry>
			</collision>
		</link>
		<link name="wheel_2">
			<pose>0.17784615384615385 0.22499999999999998 0.075 0 1.5707 0</pose>
			<visual name="wheel_2_vis">
				<geometry>
					<cylinder>
						<radius>0.075</radius>
						<length>0.05769230769230769</length>
					</cylinder>
				</geometry>
			</visual>
			<collision name="wheel_2_col">
				<geometry>
					<cylinder>
						<radius>0.075</radius>
						<length>0.05769230769230769</length>
					</cylinder>
				</geometry>
			</collision>
		</link>
		<joint name="susp2_body" type="revolute">
			<pose>0 0 0.04875 0 0 0</pose>
			<child>susp_2</child>
			<parent>body_link</parent>
			<axis>
				<xyz>0 0 1</xyz>
				<dynamics>
					<friction>0.5</friction>
					<damping>0.3</damping>
				</dynamics>
				<limit>
					<upper>1.0471975511965976</upper>
					<lower>-1.0471975511965976</lower>
				</limit>
			</axis>
		</joint>
		<joint name="susp_wheel_2" type="revolute">
			<pose>0 0 0 0 0 0</pose>
			<child>wheel_2</child>
			<parent>susp_2</parent>
			<axis>
				<xyz>1 0 0</xyz>
				<dynamics>
					<friction>0.5</friction>
					<damping>0.3</damping>
				</dynamics>
			</axis>
		</joint>
		<link name="susp_4">
			<pose>-0.13125 -0.22499999999999998 0.12375 0 0 0</pose>
			<visual name="susp_4_vis">
				<geometry>
					<cylinder>
						<radius>0.01875</radius>
						<length>0.0975</length>
					</cylinder>
				</geometry>
			</visual>
			<collision name="susp_4_col">
				<geometry>
					<cylinder>
						<radius>0.01875</radius>
						<length>0.0975</length>
					</cylinder>
				</geometry>
			</collision>
		</link>
		<link name="wheel_4">
			<pose>-0.17884615384615385 -0.22499999999999998 0.075 0 1.5707 0</pose>
			<visual name="wheel_4_vis">
				<geometry>
					<cylinder>
						<radius>0.075</radius>
						<length>0.05769230769230769</length>
					</cylinder>
				</geometry>
			</visual>
			<collision name="wheel_4_col">
				<geometry>
					<cylinder>
						<radius>0.075</radius>
						<length>0.05769230769230769</length>
					</cylinder>
				</geometry>
			</collision>
		</link>
		<joint name="susp4_body" type="revolute">
			<pose>0 0 0.04875 0 0 0</pose>
			<child>susp_4</child>
			<parent>body_link</parent>
			<axis>
				<xyz>0 0 1</xyz>
				<dynamics>
					<friction>0.5</friction>
					<damping>0.3</damping>
				</dynamics>
				<limit>
					<upper>1.0471975511965976</upper>
					<lower>-1.0471975511965976</lower>
				</limit>
			</axis>
		</joint>
		<joint name="susp_wheel_4" type="revolute">
			<pose>0 0 0 0 0 0</pose>
			<child>wheel_4</child>
			<parent>susp_4</parent>
			<axis>
				<xyz>1 0 0</xyz>
				<dynamics>
					<friction>0.5</friction>
					<damping>0.3</damping>
				</dynamics>
			</axis>
		</joint>
		<link name="susp_3">
			<pose>-0.13125 0.22499999999999998 0.12375 0 0 0</pose>
			<visual name="susp_3_vis">
				<geometry>
					<cylinder>
						<radius>0.01875</radius>
						<length>0.0975</length>
					</cylinder>
				</geometry>
			</visual>
			<collision name="susp_3_col">
				<geometry>
					<cylinder>
						<radius>0.01875</radius>
						<length>0.0975</length>
					</cylinder>
				</geometry>
			</collision>
		</link>
		<link name="wheel_3">
			<pose>-0.17884615384615385 0.22499999999999998 0.075 0 1.5707 0</pose>
			<visual name="wheel_3_vis">
				<geometry>
					<cylinder>
						<radius>0.075</radius>
						<length>0.05769230769230769</length>
					</cylinder>
				</geometry>
			</visual>
			<collision name="wheel_3_col">
				<geometry>
					<cylinder>
						<radius>0.075</radius>
						<length>0.05769230769230769</length>
					</cylinder>
				</geometry>
			</collision>
		</link>
		<joint name="susp3_body" type="revolute">
			<pose>0 0 0.04875 0 0 0</pose>
			<child>susp_3</child>
			<parent>body_link</parent>
			<axis>
				<xyz>0 0 1</xyz>
				<dynamics>
					<friction>0.5</friction>
					<damping>0.3</damping>
				</dynamics>
				<limit>
					<upper>1.0471975511965976</upper>
					<lower>-1.0471975511965976</lower>
				</limit>
			</axis>
		</joint>
		<joint name="susp_wheel_3" type="revolute">
			<pose>0 0 0 0 0 0</pose>
			<child>wheel_3</child>
			<parent>susp_3</parent>
			<axis>
				<xyz>1 0 0</xyz>
				<dynamics>
					<friction>0.5</friction>
					<damping>0.3</damping>
				</dynamics>
			</axis>
		</joint>
		<plugin filename="libplugin_wheel.so" name="test_plug">
			<proportional_pid>4.0</proportional_pid>
			<integral_pid>1.8</integral_pid>
			<derivative_pid>0.004</derivative_pid>
			<velocity>5</velocity>
		</plugin>
	</model>
</sdf>
