<?xml version="1.0" ?>
<sdf version="1.6">
	<model name="RobotArm">
		<link name="arm_base">
			<pose>0 0 0.0075 0 0 0</pose>
			<inertial>
				<inertia>
					<ixx>0.24375000</ixx>
					<iyy>0.24375000</iyy>
					<izz>0.45000000</izz>
				</inertia>
				<mass>1000.00000000</mass>
			</inertial>
			<visual name="arm_base_vis">
				<geometry>
					<cylinder>
						<radius>0.03</radius>
						<length>0.015</length>
					</cylinder>
				</geometry>
			</visual>
			<collision name="arm_base_col">
				<geometry>
					<cylinder>
						<radius>0.03</radius>
						<length>0.015</length>
					</cylinder>
				</geometry>
			</collision>
		</link>
		<joint name="bodyLink_armBase" type="fixed">
			<pose>0 0 0 0 0 0</pose>
			<child>arm_base</child>
			<parent>body_link</parent>
		</joint>
		<link name="arm_base_top">
			<pose>0 0 0.03 0 0 0</pose>
			<inertial>
				<inertia>
					<ixx>0.00005000</ixx>
					<iyy>0.00005000</iyy>
					<izz>0.00002500</izz>
				</inertia>
				<mass>0.50000000</mass>
			</inertial>
			<visual name="arm_base_top_vis">
				<geometry>
					<cylinder>
						<radius>0.01</radius>
						<length>0.03</length>
					</cylinder>
				</geometry>
			</visual>
			<collision name="arm_base_top_col">
				<geometry>
					<cylinder>
						<radius>0.01</radius>
						<length>0.03</length>
					</cylinder>
				</geometry>
			</collision>
		</link>
		<joint name="armBase_armBaseTop" type="revolute">
			<pose>0 0 -0.015 0 0 0</pose>
			<child>arm_base_top</child>
			<parent>arm_base</parent>
			<axis>
				<xyz>0 0 1</xyz>
				<dynamics>
					<friction>0.05</friction>
					<damping>0.03</damping>
				</dynamics>
			</axis>
		</joint>
		<link name="arm1">
			<pose>0 0 0.12 0 0 0</pose>
			<inertial>
				<inertia>
					<ixx>0.00190000</ixx>
					<iyy>0.00190000</iyy>
					<izz>0.00005000</izz>
				</inertia>
				<mass>1.00000000</mass>
			</inertial>
			<visual name="arm1_vis">
				<geometry>
					<cylinder>
						<radius>0.01</radius>
						<length>0.15</length>
					</cylinder>
				</geometry>
			</visual>
			<collision name="arm1_col">
				<geometry>
					<cylinder>
						<radius>0.01</radius>
						<length>0.15</length>
					</cylinder>
				</geometry>
			</collision>
		</link>
		<joint name="armBaseTop_arm1" type="revolute">
			<pose>0 0 -0.075 0 0 0</pose>
			<child>arm1</child>
			<parent>arm_base_top</parent>
			<axis>
				<xyz>1 0 0</xyz>
				<dynamics>
					<friction>0.05</friction>
					<damping>0.03</damping>
				</dynamics>
				<limit>
					<upper>3.141592653589793</upper>
					<lower>-3.141592653589793</lower>
				</limit>
			</axis>
		</joint>
		<link name="arm2">
			<pose>0 0 0.27 0 0 0</pose>
			<inertial>
				<inertia>
					<ixx>0.00190000</ixx>
					<iyy>0.00190000</iyy>
					<izz>0.00005000</izz>
				</inertia>
				<mass>1.00000000</mass>
			</inertial>
			<visual name="arm2_vis">
				<geometry>
					<cylinder>
						<radius>0.01</radius>
						<length>0.15</length>
					</cylinder>
				</geometry>
			</visual>
			<collision name="arm2_col">
				<geometry>
					<cylinder>
						<radius>0.01</radius>
						<length>0.15</length>
					</cylinder>
				</geometry>
			</collision>
		</link>
		<joint name="arm1_arm2" type="revolute">
			<pose>0 0 -0.075 0 0 0</pose>
			<child>arm2</child>
			<parent>arm1</parent>
			<axis>
				<xyz>1 0 0</xyz>
				<dynamics>
					<friction>0.05</friction>
					<damping>0.03</damping>
				</dynamics>
				<limit>
					<upper>3.141592653589793</upper>
					<lower>-3.141592653589793</lower>
				</limit>
			</axis>
		</joint>
		<link name="palm">
			<pose>0 0 0.35250000000000004 0 0 0</pose>
			<inertial>
				<inertia>
					<ixx>0.00000625</ixx>
					<iyy>0.00005312</iyy>
					<izz>0.00005312</izz>
				</inertia>
				<mass>0.16666667</mass>
			</inertial>
			<visual name="palm_vis">
				<geometry>
					<box>
						<size>0.06 0.015 0.015</size>
					</box>
				</geometry>
			</visual>
			<collision name="palm_col">
				<geometry>
					<box>
						<size>0.06 0.015 0.015</size>
					</box>
				</geometry>
			</collision>
		</link>
		<joint name="palm_joint" type="revolute">
			<pose>0 0 0 0 0 0</pose>
			<child>palm</child>
			<parent>arm2</parent>
			<axis>
				<xyz>1 0 0</xyz>
				<dynamics>
					<friction>0.05</friction>
					<damping>0.03</damping>
				</dynamics>
				<limit>
					<upper>3.141592653589793</upper>
					<lower>-3.141592653589793</lower>
				</limit>
			</axis>
		</joint>
		<link name="finger_one">
			<pose>0.03 0 0.37500000000000006 0 0 0</pose>
			<inertial>
				<inertia>
					<ixx>0.00002266</ixx>
					<iyy>0.00002266</iyy>
					<izz>0.00000625</izz>
				</inertia>
				<mass>0.16666667</mass>
			</inertial>
			<visual name="finger_one_vis">
				<geometry>
					<box>
						<size>0.015 0.015 0.0375</size>
					</box>
				</geometry>
			</visual>
			<collision name="finger_one_col">
				<geometry>
					<box>
						<size>0.015 0.015 0.0375</size>
					</box>
				</geometry>
			</collision>
			<sensor name="finger_one_sensor" type="contact">
				<contact>
					<collision>finger_one_col</collision>
				</contact>
				<always_on>1</always_on>
				<update_rate>30</update_rate>
				<visualize>true</visualize>
				<plugin filename="libcontact_plugin.so" name="my_plugin"/>
			</sensor>
		</link>
		<joint name="finger_one_joint" type="revolute">
			<pose>0 0 -0.01875 0 0 0</pose>
			<child>finger_one</child>
			<parent>palm</parent>
			<axis>
				<xyz>0 1 0</xyz>
				<dynamics>
					<friction>0.05</friction>
					<damping>0.03</damping>
				</dynamics>
				<limit>
					<upper>0</upper>
					<lower>0.7853981633974483</lower>
				</limit>
			</axis>
		</joint>
		<link name="finger_two">
			<pose>-0.03 0 0.37500000000000006 0 0 0</pose>
			<inertial>
				<inertia>
					<ixx>0.00002266</ixx>
					<iyy>0.00002266</iyy>
					<izz>0.00000625</izz>
				</inertia>
				<mass>0.16666667</mass>
			</inertial>
			<visual name="finger_two_vis">
				<geometry>
					<box>
						<size>0.015 0.015 0.0375</size>
					</box>
				</geometry>
			</visual>
			<collision name="finger_two_col">
				<geometry>
					<box>
						<size>0.015 0.015 0.0375</size>
					</box>
				</geometry>
			</collision>
			<sensor name="finger_two_sensor" type="contact">
				<contact>
					<collision>finger_two_col</collision>
				</contact>
				<always_on>1</always_on>
				<update_rate>30</update_rate>
				<visualize>true</visualize>
				<plugin filename="libcontact_plugin.so" name="my_plugin"/>
			</sensor>
		</link>
		<joint name="finger_two_joint" type="revolute">
			<pose>0 0 -0.01875 0 0 0</pose>
			<child>finger_two</child>
			<parent>palm</parent>
			<axis>
				<xyz>0 1 0</xyz>
				<dynamics>
					<friction>0.05</friction>
					<damping>0.03</damping>
				</dynamics>
				<limit>
					<upper>-0.7853981633974483</upper>
					<lower>0</lower>
				</limit>
			</axis>
		</joint>
		<link name="camera_link">
			<pose>0 0.015 0.35250000000000004 0 -1.5707963267948966 0</pose>
			<inertial>
				<inertia>
					<ixx>0.00000375</ixx>
					<iyy>0.00000375</iyy>
					<izz>0.00000375</izz>
				</inertia>
				<mass>0.10000000</mass>
			</inertial>
			<visual name="camera_link_vis">
				<geometry>
					<box>
						<size>0.015 0.015 0.015</size>
					</box>
				</geometry>
			</visual>
			<collision name="camera_link_col">
				<geometry>
					<box>
						<size>0.015 0.015 0.015</size>
					</box>
				</geometry>
			</collision>
		</link>
		<joint name="camera_link_joint" type="fixed">
			<pose>0 0 0 0 0 0</pose>
			<child>palm</child>
			<parent>camera_link</parent>
		</joint>
		<link name="objDistanceSensor_link">
			<pose>0 0.015 0.35250000000000004 0 -1.5707963267948966 0</pose>
			<inertial>
				<inertia>
					<ixx>0.00000375</ixx>
					<iyy>0.00000375</iyy>
					<izz>0.00000375</izz>
				</inertia>
				<mass>0.10000000</mass>
			</inertial>
			<visual name="objDistanceSensor_link_vis">
				<geometry>
					<box>
						<size>0.015 0.015 0.015</size>
					</box>
				</geometry>
			</visual>
			<collision name="objDistanceSensor_link_col">
				<geometry>
					<box>
						<size>0.015 0.015 0.015</size>
					</box>
				</geometry>
			</collision>
		</link>
		<joint name="objDistanceSensor_link_joint" type="fixed">
			<pose>0 0 0 0 0 0</pose>
			<child>palm</child>
			<parent>objDistanceSensor_link</parent>
		</joint>
		<link name="finger_one_tip">
			<pose>0.0225 0 0.40875000000000006 0 -0.5 0</pose>
			<inertial>
				<inertia>
					<ixx>0.00002266</ixx>
					<iyy>0.00002266</iyy>
					<izz>0.00000625</izz>
				</inertia>
				<mass>0.16666667</mass>
			</inertial>
			<visual name="finger_one_tip_vis">
				<geometry>
					<box>
						<size>0.015 0.015 0.0375</size>
					</box>
				</geometry>
			</visual>
			<collision name="finger_one_tip_col">
				<geometry>
					<box>
						<size>0.015 0.015 0.0375</size>
					</box>
				</geometry>
			</collision>
			<sensor name="finger_one_tip_sensor" type="contact">
				<contact>
					<collision>finger_one_tip_col</collision>
				</contact>
				<always_on>1</always_on>
				<update_rate>30</update_rate>
				<visualize>true</visualize>
				<plugin filename="libcontact_plugin.so" name="my_plugin"/>
			</sensor>
		</link>
		<joint name="finger_one_tip_joint" type="fixed">
			<pose>0 0 -0.015 0 0 0</pose>
			<child>finger_one_tip</child>
			<parent>finger_one</parent>
		</joint>
		<link name="finger_two_tip">
			<pose>-0.0225 0 0.40875000000000006 0 0.5 0</pose>
			<inertial>
				<inertia>
					<ixx>0.00002266</ixx>
					<iyy>0.00002266</iyy>
					<izz>0.00000625</izz>
				</inertia>
				<mass>0.16666667</mass>
			</inertial>
			<visual name="finger_two_tip_vis">
				<geometry>
					<box>
						<size>0.015 0.015 0.0375</size>
					</box>
				</geometry>
			</visual>
			<collision name="finger_two_tip_col">
				<geometry>
					<box>
						<size>0.015 0.015 0.0375</size>
					</box>
				</geometry>
			</collision>
			<sensor name="finger_two_tip_sensor" type="contact">
				<contact>
					<collision>finger_two_tip_col</collision>
				</contact>
				<always_on>1</always_on>
				<update_rate>30</update_rate>
				<visualize>true</visualize>
				<plugin filename="libcontact_plugin.so" name="my_plugin"/>
			</sensor>
		</link>
		<joint name="finger_two_tip_joint" type="fixed">
			<pose>0 0 -0.015 0 0 0</pose>
			<child>finger_two_tip</child>
			<parent>finger_two</parent>
		</joint>
		<plugin filename="libgripper_plugin.so" name="gripper_plugin"/>
		<plugin filename="libarm_controller.so" name="arm_controller"/>
	</model>
</sdf>
